[
  {
    "type": "part",
    "name": "top4_1",
    "xsize": 16,
    "zsize": 16,
    "slices": [
      [
        "                ",
        "                ",
        "  ###           ",
        "  ###           ",
        "  ###           ",
        "                ",
        "                ",
        "                ",
        "                ",
        "                ",
        "                ",
        "                ",
        "                ",
        "                ",
        "                ",
        "                "
      ],
      [
        "                ",
        "                ",
        "                ",
        "   :            ",
        "                ",
        "                ",
        "                ",
        "                ",
        "                ",
        "                ",
        "                ",
        "                ",
        "                ",
        "                ",
        "                ",
        "                "
      ],
      [
        "                ",
        "                ",
        "                ",
        "   :            ",
        "                ",
        "                ",
        "                ",
        "                ",
        "                ",
        "                ",
        "                ",
        "                ",
        "                ",
        "                ",
        "                ",
        "                "
      ],
      [
        "                ",
        "                ",
        "   :            ",
        "  :::           ",
        "   :            ",
        "                ",
        "                ",
        "                ",
        "                ",
        "                ",
        "                ",
        "                ",
        "                ",
        "                ",
        "                ",
        "                "
      ]
    ]
  },
  {
    "type": "part",
    "name": "top4_2",
    "xsize": 16,
    "zsize": 16,
    "slices": [
      [
        "                ",
        "                ",
        "                ",
        "                ",
        "                ",
        "                ",
        "                ",
        "                ",
        "                ",
        "         :  :   ",
        "         :  :   ",
        "         :  :   ",
        "         :  :   ",
        "                ",
        "                ",
        "                "
      ],
      [
        "                ",
        "                ",
        "                ",
        "                ",
        "                ",
        "                ",
        "                ",
        "                ",
        "                ",
        "         :  :   ",
        "         :  :   ",
        "         :  :   ",
        "         :  :   ",
        "                ",
        "                ",
        "                "
      ],
      [
        "                ",
        "                ",
        "                ",
        "                ",
        "                ",
        "                ",
        "                ",
        "                ",
        "                ",
        "         ____   ",
        "         ____   ",
        "         ____   ",
        "         ____   ",
        "                ",
        "                ",
        "                "
      ]
    ]
  },
  {
    "type": "part",
    "name": "top4_3",
    "xsize": 16,
    "zsize": 16,
    "slices": [
      [
        "                ",
        "                ",
        "                ",
        "                ",
        "                ",
        "                ",
        "                ",
        "                ",
        "         ::::   ",
        "         :  :   ",
        "         :  :   ",
        "         :  :   ",
        "         :  :   ",
        "                ",
        "                ",
        "                "
      ]
    ]
  },
  {
    "type": "part",
    "name": "building4_1",
    "xsize": 16,
    "zsize": 16,
    "slices": [
      [
        "#SSSSSSSSSSSSSS#",
        "S##############S",
        "S##############S",
        "S##############S",
        "S##############S",
        "S##############S",
        "S#####1########S",
        "S##############S",
        "S##############S",
        "S##############S",
        "S#########  ###S",
        "S#########  ###S",
        "S#########  ###S",
        "S#########cc###S",
        "S##############S",
        "#SSSSSSSSSSSSSS#"
      ],
      [
        "#aa#aa#aa#aa#aa#",
        "a22222#  N  N 3a",
        "a2   2#  7     a",
        "#C  3          #",
        "a2   2#    7   a",
        "a22222#F       a",
        "#######F 7     #",
        "aSSSSS#2       a",
        "a 7  S#   cc   a",
        "#    S#  :dd:  #",
        "aU    #  :  :  a",
        "aN       :  :  a",
        "#U   F#  :  :  #",
        "a   UN#        a",
        "a3   F#      33a",
        "#aa#aa#aa#aa#aa#"
      ],
      [
        "#aa#aa#aa#aa#aa#",
        "a     #  *  *  a",
        "a     #        a",
        "#              #",
        "a     #        a",
        "a     #        a",
        "##:::##T       #",
        "a*****#        a",
        "a    *#        a",
        "#    *#   cc   #",
        "a     #   dd   a",
        "a*             a",
        "#     #        #",
        "a    *#        a",
        "a     #        a",
        "#aa#aa#aa#aa#aa#"
      ],
      [
        "#aa#aa#aa#aa#aa#",
        "a     #        a",
        "a     #        a",
        "#     #        #",
        "a     #        a",
        "a     #        a",
        "#######        #",
        "a     #        a",
        "a     #        a",
        "#     #        #",
        "a     #   cc   a",
        "a     #   dd   a",
        "#     #        #",
        "a     #        a",
        "a     #        a",
        "#aa#aa#aa#aa#aa#"
      ],
      [
        "#SSSSSSSSSSSSSS#",
        "S##############S",
        "S##############S",
        "S##############S",
        "S##############S",
        "S##############S",
        "S##############S",
        "S##############S",
        "S#########  ###S",
        "S#########  ###S",
        "S#########  ###S",
        "S#########cc###S",
        "S##############S",
        "S##############S",
        "S##############S",
        "#SSSSSSSSSSSSSS#"
      ],
      [
        "################",
        "################",
        "################",
        "################",
        "################",
        "################",
        "################",
        "################",
        "################",
        "##########  ####",
        "##########  ####",
        "##########  ####",
        "##########cc####",
        "################",
        "################",
        "################"
      ]
    ]
  },
  {
    "type": "part",
    "name": "building4_2",
    "xsize": 16,
    "zsize": 16,
    "slices": [
      [
        "#SSSSSSSSSSSSSS#",
        "S##############S",
        "S##############S",
        "S##############S",
        "S##############S",
        "S##############S",
        "S###1##########S",
        "S##############S",
        "S##############S",
        "S##############S",
        "S#########  ###S",
        "S#########  ###S",
        "S#########  ###S",
        "S#########cc###S",
        "S##############S",
        "#SSSSSSSSSSSSSS#"
      ],
      [
        "#aa#aa#aa#aa#aa#",
        "a33       7    a",
        "a3  7         3a",
        "#             F#",
        "a      UU      a",
        "a  CFF NN     7a",
        "##########  ####",
        "a SSSSSSS      a",
        "a         cc3  a",
        "#7  U  U :dd:  #",
        "a        :  :  a",
        "a     3  :  :  a",
        "#7  U  U :  :  #",
        "a              a",
        "a  F           a",
        "#aa#aa#aa#aa#aa#"
      ],
      [
        "#aa#aa#aa#aa#aa#",
        "a              a",
        "a              a",
        "#              #",
        "a              a",
        "a    T **      a",
        "#######aa#  #aa#",
        "a  * **3*      a",
        "a              a",
        "#         cc   #",
        "a         dd   a",
        "a              a",
        "#              #",
        "a              a",
        "a              a",
        "#aa#aa#aa#aa#aa#"
      ],
      [
        "#aa#aa#aa#aa#aa#",
        "a              a",
        "a              a",
        "#              #",
        "a              a",
        "a              a",
        "#######aa#  #aa#",
        "a              a",
        "a              a",
        "#              #",
        "a         cc   a",
        "a         dd   a",
        "#              #",
        "a              a",
        "a              a",
        "#aa#aa#aa#aa#aa#"
      ],
      [
        "#SSSSSSSSSSSSSS#",
        "S##############S",
        "S##############S",
        "S##############S",
        "S##############S",
        "S##############S",
        "S##############S",
        "S##############S",
        "S#########  ###S",
        "S#########  ###S",
        "S#########  ###S",
        "S#########cc###S",
        "S##############S",
        "S##############S",
        "S##############S",
        "#SSSSSSSSSSSSSS#"
      ],
      [
        "################",
        "################",
        "################",
        "################",
        "################",
        "################",
        "################",
        "################",
        "################",
        "##########  ####",
        "##########  ####",
        "##########  ####",
        "##########cc####",
        "################",
        "################",
        "################"
      ]
    ]
  },
  {
    "type": "part",
    "name": "building4_3",
    "xsize": 16,
    "zsize": 16,
    "slices": [
      [
        "#SSSSSSSSSSSSSS#",
        "S##############S",
        "S##############S",
        "S##############S",
        "S##############S",
        "S##############S",
        "S##############S",
        "S##############S",
        "S##############S",
        "S##############S",
        "S#########  ###S",
        "S#########  ###S",
        "S#########  ###S",
        "S#########cc###S",
        "S##############S",
        "#SSSSSSSSSSSSSS#"
      ],
      [
        "#aa#aa#aa#aa#aa#",
        "aIIIII#  7  7 3a",
        "a 3  IQ       3a",
        "#    IQ   7    #",
        "a  3 IQ     3  a",
        "a  IIIQ        a",
        "#  UU #   3    #",
        "a              a",
        "a         cc   a",
        "#     #  :dd:  #",
        "a    FQ  :  :  a",
        "a   UNQ  :  :  a",
        "#7  UNQ  :  :  #",
        "a    FQ3      3a",
        "a  7  #3     33a",
        "#aa#aa#aa#aa#aa#"
      ],
      [
        "#aa#aa#aa#aa#aa#",
        "a66666#        a",
        "a    6Q        a",
        "#    6Q        #",
        "a    6Q        a",
        "a  666Q        a",
        "#     #        #",
        "a              a",
        "a              a",
        "#     #   cc   #",
        "a     Q   dd   a",
        "a    *Q        a",
        "#    *Q        #",
        "a     Q        a",
        "a     #        a",
        "#aa#aa#aa#aa#aa#"
      ],
      [
        "#aa#aa#aa#aa#aa#",
        "aOOOOO#        a",
        "a    OQ        a",
        "#    OQ        #",
        "a    OQ        a",
        "a    OQ        a",
        "#     #        #",
        "a     #        a",
        "a     #        a",
        "#     #        #",
        "a     Q   cc   a",
        "a     Q   dd   a",
        "#     Q        #",
        "a     Q        a",
        "a     #        a",
        "#aa#aa#aa#aa#aa#"
      ],
      [
        "#SSSSSSSSSSSSSS#",
        "S##############S",
        "S##############S",
        "S##############S",
        "S##############S",
        "S##############S",
        "S##############S",
        "S##############S",
        "S#########  ###S",
        "S#########  ###S",
        "S#########  ###S",
        "S#########cc###S",
        "S##############S",
        "S##############S",
        "S##############S",
        "#SSSSSSSSSSSSSS#"
      ],
      [
        "################",
        "################",
        "################",
        "################",
        "################",
        "################",
        "################",
        "################",
        "################",
        "##########  ####",
        "##########  ####",
        "##########  ####",
        "##########cc####",
        "################",
        "################",
        "################"
      ]
    ]
  },
  {
    "type": "part",
    "name": "building4_4",
    "xsize": 16,
    "zsize": 16,
    "slices": [
      [
        "#SSSSSSSSSSSSSS#",
        "S##############S",
        "S##############S",
        "S##############S",
        "S##############S",
        "S##############S",
        "S##############S",
        "S##############S",
        "S##############S",
        "S##############S",
        "S#########  ###S",
        "S#########  ###S",
        "S#########  ###S",
        "S#########cc###S",
        "S##############S",
        "#SSSSSSSSSSSSSS#"
      ],
      [
        "#######aa#aa#aa#",
        "#3 M 3#       3a",
        "#7   M#7  UNU  a",
        "#M    #        #",
        "#     #7  UNU  a",
        "# M   #     3  a",
        "####  #7  UNU  #",
        "a              a",
        "a         cc   a",
        "#     #  :dd:  #",
        "a    F:  :  :  a",
        "a    F:  :  :  a",
        "#   UN#  :  :  #",
        "a3   F:       3a",
        "a3 7 F:  7  7  a",
        "#aa#aa#aa#aa#aa#"
      ],
      [
        "#######aa#aa#aa#",
        "#     #        a",
        "#     #   * *  a",
        "#     #        #",
        "#     #   * *  a",
        "#     #        a",
        "####  #   * *  #",
        "a              a",
        "a              a",
        "#     #   cc   #",
        "a     :   dd   a",
        "a     :        a",
        "#    *#        #",
        "a     :        a",
        "a     :        a",
        "#aa#aa#aa#aa#aa#"
      ],
      [
        "#a###a#aa#aa#aa#",
        "a     :        a",
        "#     :        a",
        "#     #        #",
        "#     :        a",
        "a     :        a",
        "#::#  #        #",
        "a              a",
        "a              a",
        "#     #        #",
        "a     :   cc   a",
        "a     :   dd   a",
        "#     #        #",
        "a     :        a",
        "a     :        a",
        "#aa#aa#aa#aa#aa#"
      ],
      [
        "#SSSSSSSSSSSSSS#",
        "S##############S",
        "S##############S",
        "S##############S",
        "S##############S",
        "S##############S",
        "S##############S",
        "S##############S",
        "S#########  ###S",
        "S#########  ###S",
        "S#########  ###S",
        "S#########cc###S",
        "S##############S",
        "S##############S",
        "S##############S",
        "#SSSSSSSSSSSSSS#"
      ],
      [
        "################",
        "################",
        "################",
        "################",
        "################",
        "################",
        "################",
        "################",
        "################",
        "##########  ####",
        "##########  ####",
        "##########  ####",
        "##########cc####",
        "################",
        "################",
        "################"
      ]
    ]
  },
  {
    "type": "part",
    "name": "top_center_1",
    "xsize": 16,
    "zsize": 16,
    "slices": [
      [
        "################",
        "################",
        "################",
        "################",
        "################",
        "################",
        "################",
        "################",
        "################",
        "################",
        "################",
        "################",
        "################",
        "################",
        "################",
        "################"
      ]
    ]
  },
  {
    "type": "part",
    "name": "top_center_2",
    "xsize": 16,
    "zsize": 16,
    "slices": [
      [
        "################",
        "################",
        "################",
        "################",
        "################",
        "################",
        "################",
        "################",
        "################",
        "################",
        "################",
        "################",
        "################",
        "################",
        "################",
        "################"
      ],
      [
        "                ",
        "       3        ",
        "   :        :  *",
        "                ",
        "      3         ",
        "                ",
        "                ",
        "              3 ",
        "         3      ",
        "  3             ",
        "                ",
        "                ",
        "   :        :   ",
        "                ",
        "      3         ",
        "                "
      ],
      [
        "                ",
        "                ",
        "   :        :   ",
        "                ",
        "                ",
        "                ",
        "                ",
        "                ",
        "                ",
        "                ",
        "                ",
        "                ",
        "   :        :   ",
        "                ",
        "                ",
        "                "
      ],
      [
        "                ",
        "                ",
        "   :        :   ",
        "                ",
        "                ",
        "                ",
        "                ",
        "                ",
        "                ",
        "                ",
        "                ",
        "                ",
        "   :        :   ",
        "                ",
        "                ",
        "                "
      ]
    ]
  },
  {
    "type": "part",
    "name": "top_center_3",
    "xsize": 16,
    "zsize": 16,
    "slices": [
      [
        "################",
        "################",
        "################",
        "################",
        "################",
        "################",
        "################",
        "################",
        "################",
        "################",
        "################",
        "################",
        "################",
        "################",
        "################",
        "################"
      ],
      [
        "                ",
        "        3       ",
        "                ",
        "  3       3     ",
        "    #aaaaa#*    ",
        "    a     a     ",
        "    a     a     ",
        "          a     ",
        "    a     a     ",
        "    a     a *   ",
        "   *#aaaaa#     ",
        "    33 3  3     ",
        "                ",
        "             *  ",
        "      *         ",
        "   *            "
      ],
      [
        "                ",
        "                ",
        "                ",
        "                ",
        "    #aaaaa#     ",
        "    a     a     ",
        "    a     a     ",
        "          a     ",
        "    a     a     ",
        "    a     a     ",
        "    #aaaaa#     ",
        "                ",
        "                ",
        "                ",
        "                ",
        "                "
      ],
      [
        "                ",
        "                ",
        "                ",
        "                ",
        "    #######     ",
        "    #######     ",
        "    #######     ",
        "    #######     ",
        "    #######     ",
        "    #######     ",
        "    #######     ",
        "                ",
        "                ",
        "                ",
        "                ",
        "                "
      ]
    ]
  },
  {
    "type": "part",
    "name": "top_center_4",
    "xsize": 16,
    "zsize": 16,
    "slices": [
      [
        "################",
        "################",
        "################",
        "################",
        "################",
        "################",
        "################",
        "################",
        "################",
        "################",
        "################",
        "################",
        "################",
        "################",
        "################",
        "################"
      ],
      [
        "################",
        "#DDDDDDDDDDDDDD#",
        "#DGGDDDDDDDDDDD#",
        "#DDDDDDDDDDGDDD#",
        "#DDDDDDDDDDDDDD#",
        "#DDDGDDDDDDDDDD#",
        "#DDDDDDDGDDDDDD#",
        "#DDDDDDDDDDDDDD#",
        "#DDDGDDDDGDDDDD#",
        "#DDDDDDDDDDDDDD#",
        "#DDDDGDDDDDDGDD#",
        "#DDDDDDDDDGDDDD#",
        "#DDDDDGDDDDDDDD#",
        "#DDDDDDDDDGDDDD#",
        "#DDDGDDDDDDDDDD#",
        "################"
      ],
      [
        "        3   p   ",
        "   3            ",
        " p    p      3  ",
        "           p    ",
        "    p           ",
        "  3      p      ",
        "                ",
        "                ",
        "    p        p  ",
        "       3        ",
        "             3  ",
        "        p       ",
        "                ",
        "   p            ",
        "                ",
        "           p    "
      ]
    ]
  },
  {
    "type": "part",
    "name": "library11_1",
    "xsize": 16,
    "zsize": 16,
    "slices": [
      [
        "QQQQQQQQQQQQ#SS#",
        "QQQQQQQQQQQQ#SS#",
        "QQQQQQQQQQQQ#SS#",
        "QQQQQQQQQQQQ#SS#",
        "QQQQQQQQQQQQ#SS#",
        "QQQQQQQQQQQQ#SS#",
        "QQQQQQQQQQQQ#SS#",
        "QQQQQQQQQQQQ#SS#",
        "QQQQQQQQQQQQ#SS#",
        "QQQQQQQQQQQQ#SS#",
        "QQQQQQQQQQQQ#SS#",
        "QQQQQQQQQQQQ#SS#",
        "#############SS#",
        "SSSSSSSSSSSSSSS#",
        "SSSSSSSSSSSSSSS#",
        "################"
      ],
      [
        "               a",
        "               a",
        "  3            a",
        "               #",
        "    7 LLLL     a",
        "      3  3     a",
        "    7 LLLL     a",
        "        3      a",
        "    7 LLLL     #",
        "   3   3    3  a",
        "    7 LLLL  3  a",
        "               a",
        "               a",
        " 3       3     #",
        "               a",
        "aaa#aaaa#aaaa#aa"
      ],
      [
        "               a",
        "               a",
        "               a",
        "               #",
        "     TLLLL     a",
        "               a",
        "      LLLL     a",
        "               a",
        "      LLLL     #",
        "               a",
        "     TLLLL     a",
        "               a",
        "               a",
        "               #",
        "               a",
        "aaa#aaaa#aaaa#aa"
      ],
      [
        "               a",
        "               a",
        "               a",
        "               #",
        "      LLLL     a",
        "               a",
        "      LLLL     a",
        "               a",
        "      LLLL     #",
        "               a",
        "      LLLL     a",
        "               a",
        "               a",
        "               #",
        "               a",
        "aaa#aaaa#aaaa#aa"
      ],
      [
        "               #",
        "               #",
        "               #",
        "               #",
        "               #",
        "      %        #",
        "               #",
        "       %       #",
        "               #",
        "               #",
        "               #",
        "               #",
        "               #",
        "               #",
        "               #",
        "################"
      ],
      [
        "################",
        "################",
        "################",
        "################",
        "################",
        "################",
        "################",
        "################",
        "################",
        "################",
        "################",
        "################",
        "################",
        "################",
        "################",
        "################"
      ]
    ]
  },
  {
    "type": "part",
    "name": "library11_2",
    "xsize": 16,
    "zsize": 16,
    "slices": [
      [
        "QQQQQQQQQQQQ#SS#",
        "QQQQQQQQQQQQ#SS#",
        "QQQQQQQQQQQQ#SS#",
        "QQQQQQQQQQQQ#SS#",
        "QQQQQQQQQQQQ#SS#",
        "QQQQQQQQQQQQ#SS#",
        "QQQQQQQQQQQQ#SS#",
        "QQQQQQQQQQQQ#SS#",
        "QQQQQQQQQQQQ#SS#",
        "QQQQQQQQQQQQ#SS#",
        "QQQQQQQQQQQQ#SS#",
        "QQQQQQQQQQQQ#SS#",
        "#############SS#",
        "SSSSSSSSSSSSSSS#",
        "SSSSSSSSSSSSSSS#",
        "################"
      ],
      [
        "               a",
        "         3     a",
        " 3             a",
        "               #",
        "      LLLL  3  a",
        "   7  QQQQ  7  a",
        "      LLLL     a",
        "          3    a",
        "  3   LLLL     #",
        "   7  QQQQ  7  a",
        "    3 LLLL     a",
        "               a",
        "   3       3   a",
        "       3       #",
        "            3  a",
        "aaa#aaaa#aaaa#aa"
      ],
      [
        "               a",
        "               a",
        "               a",
        "               #",
        "     TLLLL     a",
        "      QQQQ     a",
        "      LLLL     a",
        "               a",
        "      LLLL     #",
        "      QQQQ     a",
        "     TLLLL     a",
        "               a",
        "               a",
        "               #",
        "               a",
        "aaa#aaaa#aaaa#aa"
      ],
      [
        "               a",
        "               a",
        "               a",
        "               #",
        "      * **     a",
        "      QQQQ     a",
        "      * *      a",
        "               a",
        "       **      #",
        "      QQQQ     a",
        "      3 *      a",
        "               a",
        "               a",
        "               #",
        "               a",
        "aaa#aaaa#aaaa#aa"
      ],
      [
        "               #",
        "               #",
        "               #",
        "               #",
        "         %     #",
        "      QQQQ     #",
        "       %%      #",
        "               #",
        "               #",
        "      QQQQ%    #",
        "      %        #",
        "               #",
        "               #",
        "               #",
        "   %           #",
        "################"
      ],
      [
        "################",
        "################",
        "################",
        "################",
        "################",
        "################",
        "################",
        "################",
        "################",
        "################",
        "################",
        "################",
        "################",
        "################",
        "################",
        "################"
      ]
    ]
  },
  {
    "type": "part",
    "name": "center11_1",
    "xsize": 16,
    "zsize": 16,
    "slices": [
      [
        "SQSQSQSQSQSQSQ##",
        "Q          SQS##",
        "S          QSQ# ",
        "Q          SQS# ",
        "S          QSQ# ",
        "Q          SQS##",
        "S          QSQSa",
        "Q          SQSQa",
        "S          QSQSa",
        "Q          SQSQa",
        "S          QSQ##",
        "QSQSQSQSQSQSQS# ",
        "SQSQSQSQSQSQSQ# ",
        "QSQSQSQSQSQSQS# ",
        "######SQSQ######",
        "##   #aaaa#   ##"
      ],
      [
        "::::::::::::3 ##",
        ":          :  ##",
        ":          :  a ",
        ":          :  a ",
        ":          :  a ",
        ":          :  ##",
        ":          :  3a",
        ":          :   a",
        ":          : 3 a",
        ":          :   a",
        ":          :  ##",
        "::::::::::::  a ",
        "            33a ",
        "            33a ",
        "##aaa# 73 #aaa##",
        "##   #aaaa#   ##"
      ],
      [
        "              ##",
        "              ##",
        "              a ",
        "              a ",
        "              a ",
        "              ##",
        "               a",
        "               a",
        "               a",
        "               a",
        "              ##",
        "              a ",
        "              a ",
        "              a ",
        "##aaa#    #aaa##",
        "##   #aaaa#   ##"
      ],
      [
        "              ##",
        "              ##",
        "              a ",
        "              a ",
        "              a ",
        "              ##",
        "               a",
        "               a",
        "               a",
        "               a",
        "              ##",
        "              a ",
        "              a ",
        "              a ",
        "##aaa#    #aaa##",
        "##   #aaaa#   ##"
      ],
      [
        "              ##",
        "              ##",
        "              a ",
        "              a ",
        "              a ",
        "              ##",
        "               a",
        "               a",
        "               a",
        "               a",
        "              ##",
        "              a ",
        "              a ",
        "              a ",
        "##aaa#    #aaa##",
        "##   #aaaa#   ##"
      ],
      [
        "################",
        "#          #####",
        "#          #### ",
        "#          #### ",
        "#          #### ",
        "#          #####",
        "#          ####a",
        "#          ####a",
        "#          ####a",
        "#          ####a",
        "#          #####",
        "############### ",
        "############### ",
        "############### ",
        "################",
        "##   #aaaa#   ##"
      ]
    ]
  },
  {
    "type": "part",
    "name": "top_center00_2",
    "xsize": 16,
    "zsize": 16,
    "slices": [
      [
        "################",
        "################",
        "################",
        "################",
        "################",
        "################",
        "################",
        "################",
        "################",
        "################",
        "#############  #",
        "#############  #",
        "#############  #",
        "#############  #",
        "#############))#",
        "################"
      ],
      [
        "wwwwwwwwwwwwwwww",
        "w       3      w",
        "w   7          w",
        "w       3   3  w",
        "w  3           w",
        "w              w",
        "w  3       3    ",
        "w    3          ",
        "w               ",
        "w  3        w  w",
        "w        3     w",
        "w              w",
        "w              w",
        "w  3   3       w",
        "w              w",
        "wwwwwwww    wwww"
      ],
      [
        "                ",
        "                ",
        "                ",
        "                ",
        "                ",
        "                ",
        "                ",
        "                ",
        "                ",
        "            w  w",
        "                ",
        "                ",
        "                ",
        "                ",
        "                ",
        "            w  w"
      ],
      [
        "                ",
        "                ",
        "                ",
        "                ",
        "                ",
        "                ",
        "                ",
        "                ",
        "                ",
        "            ####",
        "            ####",
        "            ####",
        "            ####",
        "            ####",
        "            ####",
        "            ####"
      ]
    ]
  },
  {
    "type": "part",
    "name": "top_center00_1",
    "xsize": 16,
    "zsize": 16,
    "slices": [
      [
        "################",
        "################",
        "################",
        "################",
        "################",
        "################",
        "################",
        "################",
        "################",
        "################",
        "#############  #",
        "#############  #",
        "#############  #",
        "#############  #",
        "#############))#",
        "################"
      ]
    ]
  },
  {
    "type": "part",
    "name": "library01_3",
    "xsize": 16,
    "zsize": 16,
    "slices": [
      [
        "#SS#QQQQQQQQQQQQ",
        "#SS#QQQQQQQQQQQQ",
        "#SS#QQQQQQQQQQQQ",
        "#SS#QQQQQQQQQQQQ",
        "#SS#QQQQQQQQQQQQ",
        "#SS#QQQQQQQQQQQQ",
        "#SS#QQQQQQQQQQQQ",
        "#SS#QQQQQQQQQQQQ",
        "#SS#QQQQQQQQQQQQ",
        "#SS#QQQQQQQQQQQQ",
        "#SS#QQQQQQQQQQQQ",
        "#SS#QQQQQQQQQQQQ",
        "#SS#############",
        "#SSSSSSSSSSSSSSS",
        "#SSSSSSSSSSSSSSS",
        "################"
      ],
      [
        "a               ",
        "aF          3   ",
        "aF     7        ",
        "#NU    7        ",
        "aF     7        ",
        "aF      3       ",
        "a               ",
        "a   3    3      ",
        "###:::::::###   ",
        "a3              ",
        "a33 LLL  NU #   ",
        "a3 7    3NU :   ",
        "a   LLL  NU : 3 ",
        "#           #  3",
        "a F     7   #33 ",
        "aa#aaaa#aaaa#aaa"
      ],
      [
        "a               ",
        "a               ",
        "a               ",
        "#*              ",
        "a               ",
        "a               ",
        "a               ",
        "a               ",
        "###:::::::###   ",
        "a               ",
        "a   LLL  *  #   ",
        "a        *  :   ",
        "a   LLLT *  :   ",
        "#           #   ",
        "a           #   ",
        "aa#aaaa#aaaa#aaa"
      ],
      [
        "a               ",
        "a               ",
        "a               ",
        "#               ",
        "a               ",
        "a               ",
        "a               ",
        "a               ",
        "###:::::::###   ",
        "a           #   ",
        "a   LLL     #   ",
        "a           :   ",
        "a   LLL     :   ",
        "#           #   ",
        "a           #   ",
        "aa#aaaa#aaaa#aaa"
      ],
      [
        "#               ",
        "#               ",
        "#               ",
        "#               ",
        "#               ",
        "#               ",
        "#               ",
        "#               ",
        "###:::::::###   ",
        "#           #   ",
        "#   **      #   ",
        "#           :   ",
        "#   * *     :   ",
        "#           #   ",
        "#           #   ",
        "################"
      ],
      [
        "################",
        "################",
        "################",
        "################",
        "################",
        "################",
        "################",
        "################",
        "################",
        "################",
        "################",
        "################",
        "################",
        "################",
        "################",
        "################"
      ]
    ]
  },
  {
    "type": "part",
    "name": "building2_4",
    "xsize": 16,
    "zsize": 16,
    "slices": [
      [
        "#$$#$$#$$#$$#$$#",
        "$##############$",
        "$###1##########$",
        "################",
        "$#####1########$",
        "$##############$",
        "################",
        "$##############$",
        "$##############$",
        "#######l########",
        "$##############$",
        "$##############$",
        "################",
        "$##############$",
        "$##############$",
        "#$$#$$#$$#$$#$$#"
      ],
      [
        "################",
        "# 3  3  3#  3  #",
        "# 3  J 3 #3  # #",
        "#   7    #   # #",
        "#  3   7 #     #",
        "# 3   3  #  3  #",
        "##########     #",
        "#              #",
        "#          3   #",
        "#      l       #",
        "#    7###7     #",
        "#             3#",
        "#     N      3 #",
        "#    UN     7  #",
        "#FFF  N       3#",
        "################"
      ],
      [
        "#aa#aa#aa#aa#aa#",
        "a        :     a",
        "a        :   * a",
        "#        :   * #",
        "a        :     a",
        "a        :     a",
        "#::::::::#     #",
        "a              a",
        "a              a",
        "#      l       #",
        "a     ###      a",
        "a      T       a",
        "#     *        #",
        "a     *        a",
        "a     *        a",
        "#aa#aa#aa#aa#aa#"
      ],
      [
        "#aa#aa#aa#aa#aa#",
        "a        :     a",
        "a        :     a",
        "#        :     #",
        "a        :     a",
        "a        :     a",
        "#::::::::#     #",
        "a              a",
        "a              a",
        "#      l       #",
        "a     ###      a",
        "a              a",
        "#              #",
        "a              a",
        "a              a",
        "#aa#aa#aa#aa#aa#"
      ],
      [
        "################",
        "################",
        "################",
        "################",
        "################",
        "################",
        "################",
        "################",
        "################",
        "#######l########",
        "################",
        "################",
        "################",
        "################",
        "################",
        "################"
      ],
      [
        "################",
        "################",
        "################",
        "################",
        "################",
        "################",
        "################",
        "################",
        "################",
        "#######l########",
        "################",
        "################",
        "################",
        "################",
        "################",
        "################"
      ]
    ]
  },
  {
    "type": "part",
    "name": "building2_3",
    "xsize": 16,
    "zsize": 16,
    "slices": [
      [
        "#$$#$$#$$#$$#$$#",
        "$##############$",
        "$###1##########$",
        "################",
        "$#####1########$",
        "$##############$",
        "################",
        "$##############$",
        "$##############$",
        "#######l########",
        "$##############$",
        "$##############$",
        "################",
        "$##############$",
        "$##############$",
        "#$$#$$#$$#$$#$$#"
      ],
      [
        "################",
        "#888     N 888 #",
        "#   ###8 N    8#",
        "#   ###8UN  3 8#",
        "#   ###8 N    3#",
        "#888     N  3 F#",
        "##########    F#",
        "#     3  #    N#",
        "#  3  3  #    F#",
        "#      l #    F#",
        "#  #######     #",
        "# 3 88888     8#",
        "#        3    8#",
        "#     3       8#",
        "#  LLLLLLL 888 #",
        "################"
      ],
      [
        "#aa#aa#aa#aa#aa#",
        "a888       888 a",
        "a             8a",
        "#    C        8#",
        "a              a",
        "a888    T      a",
        "####aaa###     #",
        "a       T#    *a",
        "a        #     a",
        "#      l #     #",
        "a  #######     a",
        "a   88888     8a",
        "#             8#",
        "a             8a",
        "a  ******* 888 a",
        "#aa#aa#aa#aa#aa#"
      ],
      [
        "#aa#aa#aa#aa#aa#",
        "a              a",
        "a              a",
        "#              #",
        "a              a",
        "a              a",
        "##########     #",
        "a        #     a",
        "a        #     a",
        "#      l #     #",
        "a  #######     a",
        "a              a",
        "#             L#",
        "a              a",
        "a              a",
        "#aa#aa#aa#aa#aa#"
      ],
      [
        "################",
        "################",
        "################",
        "################",
        "################",
        "################",
        "################",
        "################",
        "################",
        "#######l########",
        "################",
        "################",
        "################",
        "################",
        "################",
        "################"
      ],
      [
        "################",
        "################",
        "################",
        "################",
        "################",
        "################",
        "################",
        "################",
        "################",
        "#######l########",
        "################",
        "################",
        "################",
        "################",
        "################",
        "################"
      ]
    ]
  },
  {
    "type": "part",
    "name": "building2_2",
    "xsize": 16,
    "zsize": 16,
    "slices": [
      [
        "#$$#$$#$$#$$#$$#",
        "$##############$",
        "$##############$",
        "################",
        "$##############$",
        "$##############$",
        "################",
        "$##############$",
        "$##############$",
        "#######l########",
        "$##############$",
        "$##############$",
        "################",
        "$##############$",
        "$##############$",
        "#$$#$$#$$#$$#$$#"
      ],
      [
        "################",
        "#22222222#   7 #",
        "#       7#   7 #",
        "# 55555  # 3 7 #",
        "#     5  #     #",
        "# 55555        #",
        "#  7     #    3#",
        "######## #     #",
        "#73      #  3  #",
        "####   l #     #",
        "# C#######     #",
        "#           3  #",
        "#   3          #",
        "#       1   1  #",
        "#  FF FF  FF   #",
        "################"
      ],
      [
        "#aa#aa#aa#aa#aa#",
        "a        #     a",
        "a        #     a",
        "#        #     #",
        "a        #     a",
        "a              a",
        "a        #     a",
        "########T#     #",
        "a        #     a",
        "####   l #     #",
        "a  #######     a",
        "a              a",
        "#              #",
        "a              a",
        "a              a",
        "#aa#aa#aa#aa#aa#"
      ],
      [
        "#aa#aa#aa#aa#aa#",
        "a        #     a",
        "a        #     a",
        "#        #     #",
        "a        #     a",
        "a        #     a",
        "a        #     a",
        "##########     #",
        "a        #     a",
        "####   l #     #",
        "a  #######     a",
        "a              a",
        "#              #",
        "a              a",
        "a              a",
        "#aa#aa#aa#aa#aa#"
      ],
      [
        "################",
        "################",
        "################",
        "################",
        "################",
        "################",
        "################",
        "################",
        "################",
        "#######l########",
        "################",
        "################",
        "################",
        "################",
        "################",
        "################"
      ],
      [
        "################",
        "################",
        "################",
        "################",
        "################",
        "################",
        "################",
        "################",
        "################",
        "#######l########",
        "################",
        "################",
        "################",
        "################",
        "################",
        "################"
      ]
    ]
  },
  {
    "type": "part",
    "name": "center00_1",
    "xsize": 16,
    "zsize": 16,
    "slices": [
      [
        "##   #aaaa#   ##",
        "######QSQS######",
        " #SQSQSQSQSQSQSQ",
        " #QSQSQSQSQSQSQS",
        " #SQSQSQSQSQSQSQ",
        "##QSQSQSQSQSQSQS",
        "aQSQSQSQSQSQSQSQ",
        "aSQSQSQSQSQSQSQS",
        "aQSQSQSQSQSQSQSQ",
        "aSQSQSQSQSQSQSQS",
        "##SQSQSQSQSQS  Q",
        " #QSQSQSQSQSQ  S",
        " #SQSQSQSQSQS  Q",
        " #QSQSQSQSQSQ  S",
        "##SQSQSQSQSQS))Q",
        "##QSQSQSQSQSQSQS"
      ],
      [
        "##   #aaaa#   ##",
        "##aaa# J  #aaa##",
        " a         3    ",
        " a     3        ",
        " a            3 ",
        "##              ",
        "a           3   ",
        "a  3            ",
        "a        3      ",
        "a            )) ",
        "##          Q  Q",
        " a    3    NQ  Q",
        " a         NQ  Q",
        " a         NQ  Q",
        "##  3       Q  Q",
        "##              "
      ],
      [
        "##   #aaaa#   ##",
        "##aaa#    #aaa##",
        " a              ",
        " a              ",
        " a              ",
        "##              ",
        "a               ",
        "a               ",
        "a               ",
        "a               ",
        "##          a))a",
        " a         *a  a",
        " a         *a  a",
        " a         *a  a",
        "##          a  a",
        "##              "
      ],
      [
        "##   #aaaa#   ##",
        "##aaa#    #aaa##",
        " a              ",
        " a              ",
        " a              ",
        "##              ",
        "a               ",
        "a               ",
        "a               ",
        "a               ",
        "##          a  a",
        " a          a))a",
        " a          a  a",
        " a          a  a",
        "##          a  a",
        "##              "
      ],
      [
        "##   #aaaa#   ##",
        "##aaa#    #aaa##",
        " a              ",
        " a              ",
        " a              ",
        "##              ",
        "a               ",
        "a               ",
        "a               ",
        "a               ",
        "##          a  a",
        " a          a  a",
        " a          a))a",
        " a          a  a",
        "##          a  a",
        "##              "
      ],
      [
        "##   #aaaa#   ##",
        "################",
        " ###############",
        " ###############",
        " ###############",
        "################",
        "a###############",
        "a###############",
        "a###############",
        "a###############",
        "#############  #",
        " ############  #",
        " ############  #",
        " ############))#",
        "#############  #",
        "################"
      ]
    ]
  },
  {
    "type": "part",
    "name": "building2_1",
    "xsize": 16,
    "zsize": 16,
    "slices": [
      [
        "#$$#$$#$$#$$#$$#",
        "$##############$",
        "$##############$",
        "################",
        "$##############$",
        "$##############$",
        "################",
        "$##############$",
        "$##############$",
        "#######l########",
        "$##############$",
        "$##############$",
        "################",
        "$##############$",
        "$##############$",
        "#$$#$$#$$#$$#$$#"
      ],
      [
        "################",
        "#              #",
        "#  U  U  U  U  #",
        "#              #",
        "#  U  U  U  U  #",
        "#              #",
        "#  U  U  U  U  #",
        "#              #",
        "#  U  U  U  U  #",
        "#      l       #",
        "#     ###      #",
        "#   NNNNNNN    #",
        "#              #",
        "#              #",
        "#  IIIIIIIIII  #",
        "################"
      ],
      [
        "#aa#aa#aa#aa#aa#",
        "a              a",
        "a              a",
        "#              #",
        "a              a",
        "a              a",
        "#              #",
        "a              a",
        "a              a",
        "#      l       #",
        "a     ###      a",
        "a   *******    a",
        "#              #",
        "a              a",
        "a  6666666666  a",
        "#aa#aa#aa#aa#aa#"
      ],
      [
        "#aa#aa#aa#aa#aa#",
        "a              a",
        "a              a",
        "#              #",
        "a              a",
        "a              a",
        "#              #",
        "a              a",
        "a              a",
        "#      l       #",
        "a     ###      a",
        "a              a",
        "#              #",
        "a              a",
        "a  O  O  O  O  a",
        "#aa#aa#aa#aa#aa#"
      ],
      [
        "################",
        "################",
        "################",
        "################",
        "################",
        "################",
        "################",
        "################",
        "################",
        "#######l########",
        "################",
        "################",
        "################",
        "################",
        "################",
        "################"
      ],
      [
        "################",
        "################",
        "################",
        "################",
        "################",
        "################",
        "################",
        "################",
        "################",
        "#######l########",
        "################",
        "################",
        "################",
        "################",
        "################",
        "################"
      ]
    ]
  },
  {
    "type": "part",
    "name": "library01_2",
    "xsize": 16,
    "zsize": 16,
    "slices": [
      [
        "#SS#QQQQQQQQQQQQ",
        "#SS#QQQQQQQQQQQQ",
        "#SS#QQQQQQQQQQQQ",
        "#SS#QQQQQQQQQQQQ",
        "#SS#QQQQQQQQQQQQ",
        "#SS#QQQQQQQQQQQQ",
        "#SS#QQQQQQQQQQQQ",
        "#SS#QQQQQQQQQQQQ",
        "#SS#QQQQQQQQQQQQ",
        "#SS#QQQQQQQQQQQQ",
        "#SS#QQQQQQQQQQQQ",
        "#SS#QQQQQQQQQQQQ",
        "#SS#############",
        "#SSSSSSSSSSSSSSS",
        "#SSSSSSSSSSSSSSS",
        "################"
      ],
      [
        "a    3    3     ",
        "a   3           ",
        "a        3      ",
        "#            3  ",
        "a   3 FLLLLF    ",
        "a     QQQQQQ    ",
        "a 3   QLLLLQ    ",
        "a     QUUUUQ    ",
        "#         3     ",
        "a     QUUUUQ  3 ",
        "a  3  QLLLLQ    ",
        "a     QQQQQQ    ",
        "a     FLLLLF    ",
        "# 3          3  ",
        "a    3    3     ",
        "aa#aaaa#aaaa#aaa"
      ],
      [
        "a               ",
        "a               ",
        "a               ",
        "#               ",
        "a               ",
        "a      ***      ",
        "a               ",
        "a               ",
        "#               ",
        "a               ",
        "a               ",
        "a      * * *    ",
        "a               ",
        "#               ",
        "a               ",
        "aa#aaaa#aaaa#aaa"
      ],
      [
        "a               ",
        "a               ",
        "a               ",
        "#               ",
        "a               ",
        "a               ",
        "a               ",
        "a               ",
        "#               ",
        "a               ",
        "a               ",
        "a               ",
        "a               ",
        "#               ",
        "a               ",
        "aa#aaaa#aaaa#aaa"
      ],
      [
        "#               ",
        "#               ",
        "#               ",
        "#               ",
        "#               ",
        "#               ",
        "#               ",
        "#               ",
        "#               ",
        "#               ",
        "#               ",
        "#               ",
        "#               ",
        "#               ",
        "#               ",
        "################"
      ],
      [
        "################",
        "################",
        "################",
        "################",
        "################",
        "################",
        "################",
        "################",
        "################",
        "################",
        "################",
        "################",
        "################",
        "################",
        "################",
        "################"
      ]
    ]
  },
  {
    "type": "part",
    "name": "center00_3",
    "xsize": 16,
    "zsize": 16,
    "slices": [
      [
        "##   #aaaa#   ##",
        "######QSQS######",
        " #SQSQSQSQSQSQSQ",
        " #QSQSQSQSQSQSQS",
        " #SQSQSQSQSQSQSQ",
        "##QSQSQSQSQSQSQS",
        "aQSQSQSQSQSQSQSQ",
        "aSQSQSQSQSQSQSQS",
        "aQSQSQSQSQSQSQSQ",
        "aSQSQSQSQSQSQSQS",
        "##SQSQSQSQSQS  Q",
        " #QSQSQSQSQSQ  S",
        " #SQSQSQSQSQS  Q",
        " #QSQSQSQSQSQ  S",
        "##SQSQSQSQSQS))Q",
        "##QSQSQSQSQSQSQS"
      ],
      [
        "##   #aaaa#   ##",
        "##aaa#NNNN#aaa##",
        " a        3     ",
        " a    3      3  ",
        " a              ",
        "##  3           ",
        "aF        3     ",
        "aF           3  ",
        "aF    3         ",
        "aF           )) ",
        "#########   Q  Q",
        " a FF ###   Q  Q",
        " a    ###   Q  Q",
        " a    ###   Q  Q",
        "### #####   Q  Q",
        "##              "
      ],
      [
        "##   #aaaa#   ##",
        "##aaa#****#aaa##",
        " a              ",
        " a              ",
        " a              ",
        "##              ",
        "a               ",
        "a               ",
        "a               ",
        "a    T          ",
        "#########   a))a",
        " a    ###   a  a",
        " a    ###   a  a",
        " a    ###   a  a",
        "### #####   a  a",
        "##              "
      ],
      [
        "##   #aaaa#   ##",
        "##aaa#    #aaa##",
        " a              ",
        " a              ",
        " a              ",
        "##              ",
        "a               ",
        "a               ",
        "a               ",
        "a               ",
        "#########   a  a",
        " a    ###   a))a",
        " a    ###   a  a",
        " a    ###   a  a",
        "### #####   a  a",
        "##              "
      ],
      [
        "##   #aaaa#   ##",
        "##aaa#    #aaa##",
        " a              ",
        " a              ",
        " a              ",
        "##              ",
        "a               ",
        "a               ",
        "a               ",
        "a               ",
        "#########   a  a",
        " a    ###   a  a",
        " a    ###   a))a",
        " a    ###   a  a",
        "### #####   a  a",
        "##              "
      ],
      [
        "##   #aaaa#   ##",
        "################",
        " ###############",
        " ###############",
        " ###############",
        "################",
        "a###############",
        "a###############",
        "a###############",
        "a###############",
        "#############  #",
        " ############  #",
        " ############  #",
        " ############))#",
        "#############  #",
        "################"
      ]
    ]
  },
  {
    "type": "part",
    "name": "library01_1",
    "xsize": 16,
    "zsize": 16,
    "slices": [
      [
        "#SS#QQQQQQQQQQQQ",
        "#SS#QQQQQQQQQQQQ",
        "#SS#QQQQQQQQQQQQ",
        "#SS#QQQQQQQQQQQQ",
        "#SS#QQQQQQQQQQQQ",
        "#SS#QQQQQQQQQQQQ",
        "#SS#QQQQQQQQQQQQ",
        "#SS#QQQQQQQQQQQQ",
        "#SS#QQQQQQQQQQQQ",
        "#SS#QQQQQQQQQQQQ",
        "#SS#QQQQQQQQQQQQ",
        "#SS#QQQQQQQQQQQQ",
        "#SS#############",
        "#SSSSSSSSSSSSSSS",
        "#SSSSSSSSSSSSSSS",
        "################"
      ],
      [
        "a               ",
        "a   3           ",
        "a        3      ",
        "#       %    3  ",
        "a      LLLL     ",
        "a  3            ",
        "a      LLLL     ",
        "a        %%     ",
        "#    3 LLLL     ",
        "a        3      ",
        "a      LLLL   3 ",
        "a      %%       ",
        "a               ",
        "#               ",
        "a         33  33",
        "aa#aaaa#aaaa#aaa"
      ],
      [
        "a               ",
        "a               ",
        "a               ",
        "#               ",
        "a      LLLLT    ",
        "a               ",
        "a      LLLL     ",
        "a               ",
        "#      LLLL     ",
        "a               ",
        "a      LLLLT    ",
        "a               ",
        "a               ",
        "#               ",
        "a               ",
        "aa#aaaa#aaaa#aaa"
      ],
      [
        "a               ",
        "a               ",
        "a               ",
        "#               ",
        "a      LLLL     ",
        "a               ",
        "a      LLLL     ",
        "a               ",
        "#      LLLL     ",
        "a               ",
        "a      LLLL     ",
        "a               ",
        "a               ",
        "#               ",
        "a               ",
        "aa#aaaa#aaaa#aaa"
      ],
      [
        "#               ",
        "#               ",
        "#               ",
        "#               ",
        "#               ",
        "#               ",
        "#               ",
        "#               ",
        "#               ",
        "#               ",
        "#               ",
        "#               ",
        "#               ",
        "#               ",
        "#               ",
        "################"
      ],
      [
        "################",
        "################",
        "################",
        "################",
        "################",
        "################",
        "################",
        "################",
        "################",
        "################",
        "################",
        "################",
        "################",
        "################",
        "################",
        "################"
      ]
    ]
  },
  {
    "type": "part",
    "name": "center00_2",
    "xsize": 16,
    "zsize": 16,
    "slices": [
      [
        "##   #aaaa#   ##",
        "######QSQS######",
        " #SQSQSQSQSQSQSQ",
        " #QSQSQSQSQSQSQS",
        " #SQSQSQSQSQSQSQ",
        "##QSQSQSQSQSQSQS",
        "aQSQSQSQSQSQSQSQ",
        "aSQSQSQSQSQSQSQS",
        "aQSQSQSQSQSQSQSQ",
        "aSQSQSQSQSQSQSQS",
        "##SQSQSQSQSQS  Q",
        " #QSQSQSQSQSQ  S",
        " #SQSQSQSQSQS  Q",
        " #QSQSQSQSQSQ  S",
        "##SQSQSQSQSQS))Q",
        "##QSQSQSQSQSQSQS"
      ],
      [
        "##   #aaaa#   ##",
        "##aaa# FJ #aaa##",
        " a            3 ",
        " a   UNU  UNU   ",
        " a              ",
        "##   UNU  UNU   ",
        "a               ",
        "a    UNU  UNU   ",
        "a   3 3         ",
        "a        3   )) ",
        "#########   Q  Q",
        " a2CC2#1#   Q  Q",
        " a2772#1#   Q  Q",
        " a2772#1# 3 Q  Q",
        "###7#####   Q  Q",
        "##7 73 3        "
      ],
      [
        "##   #aaaa#   ##",
        "##aaa#    #aaa##",
        " a              ",
        " a    *     *   ",
        " a              ",
        "##    *     *   ",
        "a               ",
        "a     *     *   ",
        "a               ",
        "a    T          ",
        "#########   a))a",
        " a    ###   a  a",
        " a    ###   a  a",
        " a    ###   a  a",
        "### #####   a  a",
        "##              "
      ],
      [
        "##   #aaaa#   ##",
        "##aaa#    #aaa##",
        " a              ",
        " a              ",
        " a              ",
        "##              ",
        "a               ",
        "a               ",
        "a               ",
        "a               ",
        "#########   a  a",
        " a    #4#   a))a",
        " a    #1#   a  a",
        " a    #1#   a  a",
        "### #####   a  a",
        "##              "
      ],
      [
        "##   #aaaa#   ##",
        "##aaa#    #aaa##",
        " a              ",
        " a              ",
        " a              ",
        "##              ",
        "a               ",
        "a               ",
        "a               ",
        "a               ",
        "#########   a  a",
        " a    ###   a  a",
        " a    ###   a))a",
        " a    ###   a  a",
        "### #####   a  a",
        "##              "
      ],
      [
        "##   #aaaa#   ##",
        "################",
        " ###############",
        " ###############",
        " ###############",
        "################",
        "a###############",
        "a###############",
        "a###############",
        "a###############",
        "#############  #",
        " ############  #",
        " ############  #",
        " ############))#",
        "#############  #",
        "################"
      ]
    ]
  },
  {
    "type": "part",
    "name": "top1x1_1",
    "xsize": 16,
    "zsize": 16,
    "slices": [
      [
        "                ",
        "                ",
        "            :   ",
        "                ",
        "                ",
        "                ",
        "                ",
        "     :   :      ",
        "                ",
        "                ",
        "                ",
        "     :   :      ",
        "                ",
        "                ",
        "                ",
        "                "
      ],
      [
        "                ",
        "                ",
        "            :   ",
        "                ",
        "                ",
        "                ",
        "                ",
        "     :   :      ",
        "                ",
        "                ",
        "                ",
        "     :   :      ",
        "                ",
        "                ",
        "                ",
        "                "
      ],
      [
        "                ",
        "                ",
        "            :   ",
        "                ",
        "                ",
        "                ",
        "                ",
        "     #####      ",
        "     #####      ",
        "     #####      ",
        "     #####      ",
        "     #####      ",
        "                ",
        "                ",
        "                ",
        "                "
      ],
      [
        "                ",
        "                ",
        "            :   ",
        "                ",
        "                ",
        "                ",
        "                ",
        "                ",
        "                ",
        "                ",
        "                ",
        "                ",
        "                ",
        "                ",
        "                ",
        "                "
      ],
      [
        "                ",
        "                ",
        "            :   ",
        "                ",
        "                ",
        "                ",
        "                ",
        "                ",
        "                ",
        "                ",
        "                ",
        "                ",
        "                ",
        "                ",
        "                ",
        "                "
      ],
      [
        "                ",
        "                ",
        "                ",
        "                ",
        "                ",
        "                ",
        "                ",
        "                ",
        "                ",
        "                ",
        "                ",
        "                ",
        "                ",
        "                ",
        "                ",
        "                "
      ]
    ]
  },
  {
    "type": "part",
    "name": "library10_5",
    "xsize": 16,
    "zsize": 16,
    "slices": [
      [
        "################",
        "SSSSSSSSSSSSSSS#",
        "SSSSSSSSSSSSSSS#",
        "#############SS#",
        "QQQQQQQQQQQQ#SS#",
        "QQQQQQQQQQQQ#SS#",
        "QQQQQQQQQQQQ#SS#",
        "QQQQQQQQQQQQ#SS#",
        "QQQQQQQQQQQQ#SS#",
        "QQQQQQQQQQQQ#SS#",
        "QQQQQQQQQQQQ#SS#",
        "QQQQQQQQQQQQ#SS#",
        "QQQQQQQQQQQQ#SS#",
        "QQQQQQQQQQQQ#SS#",
        "QQQQQQQQQQQQ#SS#",
        "QQQQQQQQQQQQ#SS#"
      ],
      [
        "aaa#aaaa#aaaa#aa",
        "        3    33a",
        "     3    3    #",
        "    FLLLLF     a",
        "  ########## 3 a",
        "  #1######1#   a",
        "  ##########3  a",
        "  ###C2C2###F  #",
        "  ###2222###L  a",
        "  ###22C2###L  a",
        "    72222###L  a",
        "  ###222C###F  a",
        "  ########## 3 #",
        "  #4######1#   a",
        "  ##########  3a",
        "    FLLLLF  3  a"
      ],
      [
        "aaa#aaaa#aaaa#aa",
        "               a",
        "               #",
        "   T LLLL      a",
        "  ##########   a",
        "  ##########   a",
        "  ##########   a",
        "  ###    ###   #",
        "  ###    ###L  a",
        "  ###    ###L  a",
        "         ###L  a",
        "  ###    ###   a",
        "  ##########   #",
        "  ##########   a",
        "  ##########   a",
        "     LLLL      a"
      ],
      [
        "aaa#aaaa#aaaa#aa",
        "               a",
        "               #",
        "     LLLL      a",
        "  ##########   a",
        "  ##########   a",
        "  ##########   a",
        "  ###    ###   #",
        "  ###    ###L  a",
        "  ###    ###L  a",
        "  ###    ###L  a",
        "  ###    ###   a",
        "  ##########   #",
        "  ##########   a",
        "  ##########   a",
        "     LLLL      a"
      ],
      [
        "################",
        "               #",
        "               #",
        "               #",
        "  ##########   #",
        "  ##########   #",
        "  ##########   #",
        "  ###%  %###   #",
        "  ###    ###   #",
        "  ###    ###   #",
        "  ###    ###   #",
        "  ###%  %###   #",
        "  ##########   #",
        "  ##########   #",
        "  ##########   #",
        "               #"
      ],
      [
        "################",
        "################",
        "################",
        "################",
        "################",
        "################",
        "################",
        "################",
        "################",
        "################",
        "################",
        "################",
        "################",
        "################",
        "################",
        "################"
      ]
    ]
  },
  {
    "type": "part",
    "name": "top1x1_5",
    "xsize": 16,
    "zsize": 16,
    "palette": [
      {
        "char": "o",
        "block": "minecraft:planks"
      }
    ],
    "slices": [
      [
        "                ",
        "                ",
        "     :          ",
        "   : : :        ",
        "                ",
        "  :: u ::       ",
        "                ",
        "   : : :        ",
        "     :          ",
        "                ",
        "                ",
        "                ",
        "                ",
        "                ",
        "                ",
        "                "
      ],
      [
        "                ",
        "                ",
        "                ",
        "   : : :        ",
        "                ",
        "   : u :        ",
        "                ",
        "   : : :        ",
        "                ",
        "                ",
        "                ",
        "                ",
        "                ",
        "                ",
        "                ",
        "                "
      ],
      [
        "                ",
        "                ",
        "                ",
        "   : : :        ",
        "                ",
        "   : u :        ",
        "                ",
        "   : : :        ",
        "                ",
        "                ",
        "                ",
        "                ",
        "                ",
        "                ",
        "                ",
        "                "
      ],
      [
        "                ",
        "                ",
        "                ",
        "   _uuu_        ",
        "   uuuuu        ",
        "   uuuuu        ",
        "   uuuuu        ",
        "   _uuu_        ",
        "                ",
        "                ",
        "                ",
        "                ",
        "                ",
        "                ",
        "                ",
        "                "
      ],
      [
        "                ",
        "                ",
        "                ",
        "    ooo         ",
        "   o   o        ",
        "   o   o        ",
        "   o   o        ",
        "    ooo         ",
        "                ",
        "                ",
        "                ",
        "                ",
        "                ",
        "                ",
        "                ",
        "                "
      ],
      [
        "                ",
        "                ",
        "                ",
        "    uuu         ",
        "   u   u        ",
        "   u   u        ",
        "   u   u        ",
        "    uuu         ",
        "                ",
        "                ",
        "                ",
        "                ",
        "                ",
        "                ",
        "                ",
        "                "
      ],
      [
        "                ",
        "                ",
        "                ",
        "    ccc         ",
        "   t   A        ",
        "   t   A        ",
        "   t   A        ",
        "    zzz         ",
        "                ",
        "                ",
        "                ",
        "                ",
        "                ",
        "                ",
        "                ",
        "                "
      ],
      [
        "                ",
        "                ",
        "                ",
        "                ",
        "    tcA         ",
        "    tuA         ",
        "    tzz         ",
        "                ",
        "                ",
        "                ",
        "                ",
        "                ",
        "                ",
        "                ",
        "                ",
        "                "
      ]
    ],
    "meta": []
  },
  {
    "type": "part",
    "name": "top1x1_2",
    "xsize": 16,
    "zsize": 16,
    "slices": [
      [
        "                ",
        "                ",
        "  ###           ",
        "  # #           ",
        "  ###           ",
        "                ",
        "    aaaaaaa     ",
        "    a:   :a     ",
        "                ",
        "                ",
        "                ",
        "    a:   :a     ",
        "    aaaaaaa     ",
        "                ",
        "                ",
        "                "
      ],
      [
        "                ",
        "                ",
        "  : :           ",
        "                ",
        "  : :           ",
        "                ",
        "    aaaaaaa     ",
        "    a:   :a     ",
        "                ",
        "                ",
        "                ",
        "    a:   :a     ",
        "    aaaaaaa     ",
        "                ",
        "                ",
        "                "
      ],
      [
        "                ",
        "                ",
        "  : :           ",
        "                ",
        "  : :           ",
        "                ",
        "    #######     ",
        "    #######     ",
        "    #######     ",
        "    #######     ",
        "    #######     ",
        "    #######     ",
        "    #######     ",
        "                ",
        "                ",
        "                "
      ],
      [
        "                ",
        "                ",
        "                ",
        "                ",
        "                ",
        "                ",
        "                ",
        "      :         ",
        "                ",
        "                ",
        "                ",
        "                ",
        "                ",
        "                ",
        "                ",
        "                "
      ],
      [
        "                ",
        "                ",
        "                ",
        "                ",
        "                ",
        "                ",
        "                ",
        "      :         ",
        "                ",
        "                ",
        "                ",
        "                ",
        "                ",
        "                ",
        "                ",
        "                "
      ],
      [
        "                ",
        "                ",
        "                ",
        "                ",
        "                ",
        "                ",
        "                ",
        "                ",
        "                ",
        "                ",
        "                ",
        "                ",
        "                ",
        "                ",
        "                ",
        "                "
      ]
    ]
  },
  {
    "type": "part",
    "name": "top1x1_3",
    "xsize": 16,
    "zsize": 16,
    "slices": [
      [
        "                ",
        "                ",
        "  ###           ",
        "  # #           ",
        "  ###           ",
        "                ",
        "    aaaaaaa     ",
        "    a:   :a     ",
        "                ",
        "                ",
        "                ",
        "    a:   :a     ",
        "    aaaaaaa     ",
        "                ",
        "                ",
        "                "
      ],
      [
        "                ",
        "                ",
        "  : :           ",
        "                ",
        "  : :           ",
        "                ",
        "    aaaaaaa     ",
        "    a:   :a     ",
        "                ",
        "                ",
        "                ",
        "    a:   :a     ",
        "    aaaaaaa     ",
        "                ",
        "                ",
        "                "
      ],
      [
        "                ",
        "                ",
        "  : :           ",
        "                ",
        "  : :           ",
        "                ",
        "    #######     ",
        "    #######     ",
        "    #######     ",
        "    #######     ",
        "    #######     ",
        "    #######     ",
        "    #######     ",
        "                ",
        "                ",
        "                "
      ],
      [
        "                ",
        "                ",
        "                ",
        "                ",
        "                ",
        "                ",
        "                ",
        "      :         ",
        "                ",
        "                ",
        "                ",
        "                ",
        "                ",
        "                ",
        "                ",
        "                "
      ],
      [
        "                ",
        "                ",
        "                ",
        "                ",
        "                ",
        "                ",
        "                ",
        "      :         ",
        "                ",
        "                ",
        "                ",
        "                ",
        "                ",
        "                ",
        "                ",
        "                "
      ],
      [
        "                ",
        "                ",
        "                ",
        "                ",
        "                ",
        "                ",
        "                ",
        "                ",
        "                ",
        "                ",
        "                ",
        "                ",
        "                ",
        "                ",
        "                ",
        "                "
      ]
    ]
  },
  {
    "type": "part",
    "name": "top1x1_4",
    "xsize": 16,
    "zsize": 16,
    "slices": [
      [
        "                ",
        "                ",
        "                ",
        "                ",
        "                ",
        "                ",
        "                ",
        "     QQ QQ      ",
        "     Q   Q      ",
        "                ",
        "     Q   Q      ",
        "     QQ QQ      ",
        "                ",
        "                ",
        "                ",
        "                "
      ],
      [
        "                ",
        "                ",
        "                ",
        "                ",
        "                ",
        "                ",
        "                ",
        "     QQ QQ      ",
        "     Q   Q      ",
        "                ",
        "     Q   Q      ",
        "     QQ QQ      ",
        "                ",
        "                ",
        "                ",
        "                "
      ],
      [
        "                ",
        "                ",
        "                ",
        "                ",
        "                ",
        "                ",
        "                ",
        "    #######     ",
        "    #######     ",
        "    #######     ",
        "    #######     ",
        "    #######     ",
        "                ",
        "                ",
        "                ",
        "                "
      ],
      [
        "                ",
        "                ",
        "                ",
        "                ",
        "                ",
        "                ",
        "                ",
        "     3          ",
        "                ",
        "        3       ",
        "       3        ",
        "       33       ",
        "                ",
        "                ",
        "                ",
        "                "
      ],
      [
        "                ",
        "                ",
        "                ",
        "                ",
        "                ",
        "                ",
        "                ",
        "                ",
        "                ",
        "                ",
        "                ",
        "                ",
        "                ",
        "                ",
        "                ",
        "                "
      ],
      [
        "                ",
        "                ",
        "                ",
        "                ",
        "                ",
        "                ",
        "                ",
        "                ",
        "                ",
        "                ",
        "                ",
        "                ",
        "                ",
        "                ",
        "                ",
        "                "
      ]
    ]
  },
  {
    "type": "part",
    "name": "library10_1",
    "xsize": 16,
    "zsize": 16,
    "slices": [
      [
        "################",
        "SSSSSSSSSSSSSSS#",
        "SSSSSSSSSSSSSSS#",
        "#############SS#",
        "QQQQQQQQQQQQ#SS#",
        "QQQQQQQQQQQQ#SS#",
        "QQQQQQQQQQQQ#SS#",
        "QQQQQQQQQQQQ#SS#",
        "QQQQQQQQQQQQ#SS#",
        "QQQQQQQQQQQQ#SS#",
        "QQQQQQQQQQQQ#SS#",
        "QQQQQQQQQQQQ#SS#",
        "QQQQQQQQQQQQ#SS#",
        "QQQQQQQQQQQQ#SS#",
        "QQQQQQQQQQQQ#SS#",
        "QQQQQQQQQQQQ#SS#"
      ],
      [
        "aaa#aaaa#aaaa#aa",
        "33             a",
        "        3      #",
        "    3       3  a",
        "     LLLL      a",
        "            3  a",
        "     LLLL    3 a",
        "               #",
        "  3  LLLL  3   a",
        "         33    a",
        "    UN  NU     a",
        "    UN  NU     a",
        "    UN  NU     #",
        "    UN  NU     a",
        "      3        a",
        "           3   a"
      ],
      [
        "aaa#aaaa#aaaa#aa",
        "               a",
        "               #",
        "               a",
        "    TLLLL      a",
        "               a",
        "     LLLL      a",
        "               #",
        "    TLLLL      a",
        "               a",
        "     *         a",
        "         *     a",
        "     *   *     #",
        "     *         a",
        "               a",
        "               a"
      ],
      [
        "aaa#aaaa#aaaa#aa",
        "               a",
        "               #",
        "               a",
        "     LLLL      a",
        "               a",
        "     LLLL      a",
        "               #",
        "     LLLL      a",
        "               a",
        "               a",
        "               a",
        "               #",
        "               a",
        "               a",
        "               a"
      ],
      [
        "################",
        "               #",
        "               #",
        "               #",
        "               #",
        "               #",
        "               #",
        "               #",
        "       %%      #",
        "               #",
        "               #",
        "               #",
        "               #",
        "               #",
        "               #",
        "               #"
      ],
      [
        "################",
        "################",
        "################",
        "################",
        "################",
        "################",
        "################",
        "################",
        "################",
        "################",
        "################",
        "################",
        "################",
        "################",
        "################",
        "################"
      ]
    ]
  },
  {
    "type": "part",
    "name": "library10_2",
    "xsize": 16,
    "zsize": 16,
    "slices": [
      [
        "################",
        "SSSSSSSSSSSSSSS#",
        "SSSSSSSSSSSSSSS#",
        "#############SS#",
        "QQQQQQQQQQQQ#SS#",
        "QQQQQQQQQQQQ#SS#",
        "QQQQQQQQQQQQ#SS#",
        "QQQQQQQQQQQQ#SS#",
        "QQQQQQQQQQQQ#SS#",
        "QQQQQQQQQQQQ#SS#",
        "QQQQQQQQQQQQ#SS#",
        "QQQQQQQQQQQQ#SS#",
        "QQQQQQQQQQQQ#SS#",
        "QQQQQQQQQQQQ#SS#",
        "QQQQQQQQQQQQ#SS#",
        "QQQQQQQQQQQQ#SS#"
      ],
      [
        "aaa#aaaa#aaaa#aa",
        "         3     a",
        "      3      3 #",
        "               a",
        "     LLLLL     a",
        "               a",
        "     U  U  U   a",
        "     N  N  N   #",
        "            3  a",
        "          3    a",
        "     N  N  N   a",
        "   3 U  U  U   a",
        "             3 #",
        "     LLLLL     a",
        "  3         3  a",
        "       3       a"
      ],
      [
        "aaa#aaaa#aaaa#aa",
        "               a",
        "               #",
        "               a",
        "    TLLLLL     a",
        "               a",
        "               a",
        "     *     *   #",
        "               a",
        "               a",
        "        *  *   a",
        "               a",
        "               #",
        "    TLLLLL     a",
        "               a",
        "               a"
      ],
      [
        "aaa#aaaa#aaaa#aa",
        "               a",
        "               #",
        "               a",
        "     LLLLL     a",
        "               a",
        "               a",
        "               #",
        "               a",
        "               a",
        "               a",
        "               a",
        "               #",
        "     LLLLL     a",
        "               a",
        "               a"
      ],
      [
        "################",
        "               #",
        "               #",
        "               #",
        "               #",
        "               #",
        "               #",
        "               #",
        "               #",
        "               #",
        "               #",
        "               #",
        "               #",
        "               #",
        "               #",
        "               #"
      ],
      [
        "################",
        "################",
        "################",
        "################",
        "################",
        "################",
        "################",
        "################",
        "################",
        "################",
        "################",
        "################",
        "################",
        "################",
        "################",
        "################"
      ]
    ]
  },
  {
    "type": "part",
    "name": "library10_3",
    "xsize": 16,
    "zsize": 16,
    "slices": [
      [
        "################",
        "SSSSSSSSSSSSSSS#",
        "SSSSSSSSSSSSSSS#",
        "#############SS#",
        "QQQQQQQQQQQQ#SS#",
        "QQQQQQQQQQQQ#SS#",
        "QQQQQQQQQQQQ#SS#",
        "QQQQQQQQQQQQ#SS#",
        "QQQQQQQQQQQQ#SS#",
        "QQQQQQQQQQQQ#SS#",
        "QQQQQQQQQQQQ#SS#",
        "QQQQQQQQQQQQ#SS#",
        "QQQQQQQQQQQQ#SS#",
        "QQQQQQQQQQQQ#SS#",
        "QQQQQQQQQQQQ#SS#",
        "QQQQQQQQQQQQ#SS#"
      ],
      [
        "aaa#aaaa#aaaa#aa",
        "          3    a",
        "    3          #",
        "            3  a",
        "    ULLLLLL    a",
        "               a",
        "    ULLLLLL%3  a",
        " 3             #",
        "    ULLLLLLC   a",
        "               a",
        " 3  ULLLLLL    a",
        "       3  3    a",
        "    ULLLLLL    #",
        "     3         a",
        "        3      a",
        "               a"
      ],
      [
        "aaa#aaaa#aaaa#aa",
        "               a",
        "               #",
        "               a",
        "    TLLLLLL    a",
        "               a",
        "     LLLLLL    a",
        "               #",
        "     LLLLLL    a",
        "               a",
        "     LLLLLL    a",
        "               a",
        "    TLLLLLL    #",
        "               a",
        "               a",
        "               a"
      ],
      [
        "aaa#aaaa#aaaa#aa",
        "               a",
        "               #",
        "               a",
        "     LLLLLL    a",
        "               a",
        "     LLLLLL    a",
        "               #",
        "     LLLLLL    a",
        "               a",
        "     LLLLLL    a",
        "               a",
        "               #",
        "               a",
        "               a",
        "               a"
      ],
      [
        "################",
        "               #",
        "               #",
        "               #",
        "     %         #",
        "               #",
        "        %      #",
        "               #",
        "               #",
        "               #",
        "               #",
        "               #",
        "               #",
        "               #",
        "               #",
        "               #"
      ],
      [
        "################",
        "################",
        "################",
        "################",
        "################",
        "################",
        "################",
        "################",
        "################",
        "################",
        "################",
        "################",
        "################",
        "################",
        "################",
        "################"
      ]
    ]
  },
  {
    "type": "part",
    "name": "center10_2",
    "xsize": 16,
    "zsize": 16,
    "slices": [
      [
        "##   #aaaa#   ##",
        "######QSQS######",
        "SQSQSQSQSQSQSQ# ",
        "QSQSQSQSQSQSQS# ",
        "SQSQSQSQSQSQSQ# ",
        "QSQSQSQSQSQSQS##",
        "SQSQSQSQSQSQSQSa",
        "QSQSQSQSQSQSQSQa",
        "SQSQSQSQSQSQSQSa",
        "QSQSQSQSQSQSQSQa",
        "SQSQSQSQSQSQSQ##",
        "QSQSQSQSQSQSQS# ",
        "SQSQSQSQSQSQSQ# ",
        "QSQSQSQSQSQSQS# ",
        "SQSQSQSQSQSQSQ##",
        "QSQSQSQSQSQSQS##"
      ],
      [
        "##   #aaaa#   ##",
        "##aaa# 7  #aaa##",
        "          3  3a ",
        "      3    3 3a ",
        "  3           a ",
        "   +++++++    ##",
        "   +QQQQQ+     a",
        " 3 +Q1QQQ+     a",
        "   +QQQ1Q+    7a",
        "   +QQQQQ+  3  a",
        "   +++++++    ##",
        " 3            a ",
        "     FF     3 a ",
        "   3 FNU      a ",
        "     FF       ##",
        "              ##"
      ],
      [
        "##   #aaaa#   ##",
        "##aaa#    #aaa##",
        "              a ",
        "              a ",
        "              a ",
        "   +++++++    ##",
        "   +QQQQQ+     a",
        "   +QQQQQ+     a",
        "   +QQQQQ+     a",
        "   +QQQQQ+     a",
        "   +++++++    ##",
        "              a ",
        "              a ",
        "              a ",
        "              ##",
        "              ##"
      ],
      [
        "##   #aaaa#   ##",
        "##aaa#    #aaa##",
        "              a ",
        "              a ",
        "              a ",
        "   +++++++    ##",
        "   +QQQQQ+     a",
        "   +QQQQQ+     a",
        "   +QQQQQ+     a",
        "   +QQQQQ+     a",
        "   +++++++    ##",
        "              a ",
        "              a ",
        "              a ",
        "              ##",
        "              ##"
      ],
      [
        "##   #aaaa#   ##",
        "##aaa#    #aaa##",
        "              a ",
        "              a ",
        "              a ",
        "   +++++++    ##",
        "   +QQQQQ+     a",
        "   +QQQQQ+     a",
        "   +QQQQQ+     a",
        "   +QQQQQ+     a",
        "   +++++++    ##",
        "              a ",
        "              a ",
        "              a ",
        "              ##",
        "              ##"
      ],
      [
        "##   #aaaa#   ##",
        "################",
        "############### ",
        "############### ",
        "############### ",
        "################",
        "###############a",
        "###############a",
        "###############a",
        "###############a",
        "################",
        "############### ",
        "############### ",
        "############### ",
        "################",
        "################"
      ]
    ]
  },
  {
    "type": "part",
    "name": "library10_4",
    "xsize": 16,
    "zsize": 16,
    "slices": [
      [
        "################",
        "SSSSSSSSSSSSSSS#",
        "SSSSSSSSSSSSSSS#",
        "#############SS#",
        "QQQQQQQQQQQQ#SS#",
        "QQQQQQQQQQQQ#SS#",
        "QQQQQQQQQQQQ#SS#",
        "QQQQQQQQQQQQ#SS#",
        "QQQQQQQQQQQQ#SS#",
        "QQQQQQQQQQQQ#SS#",
        "QQQQQQQQQQQQ#SS#",
        "QQQQQQQQQQQQ#SS#",
        "QQQQQQQQQQQQ#SS#",
        "QQQQQQQQQQQQ#SS#",
        "QQQQQQQQQQQQ#SS#",
        "QQQQQQQQQQQQ#SS#"
      ],
      [
        "aaa#aaaa#aaaa#aa",
        "   3   3       a",
        "          3    #",
        "             3 a",
        "3 UN LLLLLLU   a",
        "         3     a",
        "  UN LLLLLL% 3 a",
        "   3   33      #",
        "  UN LLLLLLC   a",
        "       3       a",
        "  UN%LLLLLLU   a",
        "          3    a",
        "  UN LLLLLLU   #",
        "               a",
        "    3   3     3a",
        "           33  a"
      ],
      [
        "aaa#aaaa#aaaa#aa",
        "               a",
        "               #",
        "               a",
        "   *TLLLLLL    a",
        "               a",
        "   * LLLLLL    a",
        "               #",
        "   * LLLLLL    a",
        "               a",
        "     LLLLLL    a",
        "               a",
        "    TLLLLLL    #",
        "               a",
        "               a",
        "               a"
      ],
      [
        "aaa#aaaa#aaaa#aa",
        "               a",
        "               #",
        "               a",
        "     LLLLLL    a",
        "               a",
        "     LLLLLL    a",
        "               #",
        "     LLLLLL    a",
        "               a",
        "     LLLLLL    a",
        "               a",
        "               #",
        "               a",
        "               a",
        "               a"
      ],
      [
        "################",
        "               #",
        "               #",
        "               #",
        "     %         #",
        "               #",
        "        %      #",
        "               #",
        "               #",
        "               #",
        "               #",
        "               #",
        "               #",
        "               #",
        "               #",
        "               #"
      ],
      [
        "################",
        "################",
        "################",
        "################",
        "################",
        "################",
        "################",
        "################",
        "################",
        "################",
        "################",
        "################",
        "################",
        "################",
        "################",
        "################"
      ]
    ]
  },
  {
    "type": "part",
    "name": "center10_1",
    "xsize": 16,
    "zsize": 16,
    "slices": [
      [
        "##   #aaaa#   ##",
        "######QSQS######",
        "SQSQSQSQSQSQSQ# ",
        "QSQSQSQSQSQSQS# ",
        "SQSQSQSQSQSQSQ# ",
        "QSQSQSQSQSQSQS##",
        "SQSQSQSQSQSQSQSa",
        "QSQSQSQSQSQSQSQa",
        "SQSQSQSQSQSQSQSa",
        "QSQSQSQSQSQSQSQa",
        "SQSQSQSQSQSQSQ##",
        "QSQSQSQSQSQSQS# ",
        "SQSQSQSQSQSQSQ# ",
        "QSQSQSQSQSQSQS# ",
        "SQSQSQSQSQSQSQ##",
        "QSQSQSQSQSQSQS##"
      ],
      [
        "##   #aaaa#   ##",
        "##aaa#    #aaa##",
        "              a ",
        "   3          a ",
        "              a ",
        "      3       ##",
        "              3a",
        "   3          Ja",
        "         3    3a",
        " 3            Fa",
        "     3        ##",
        "           3  a ",
        "        3     a ",
        "  3  3        a ",
        "         33   ##",
        "              ##"
      ],
      [
        "##   #aaaa#   ##",
        "##aaa#    #aaa##",
        "              a ",
        "              a ",
        "              a ",
        "              ##",
        "               a",
        "               a",
        "               a",
        "               a",
        "              ##",
        "              a ",
        "              a ",
        "              a ",
        "              ##",
        "              ##"
      ],
      [
        "##   #aaaa#   ##",
        "##aaa#    #aaa##",
        "              a ",
        "              a ",
        "              a ",
        "              ##",
        "               a",
        "               a",
        "               a",
        "               a",
        "              ##",
        "              a ",
        "              a ",
        "              a ",
        "              ##",
        "              ##"
      ],
      [
        "##   #aaaa#   ##",
        "##aaa#    #aaa##",
        "              a ",
        "              a ",
        "              a ",
        "              ##",
        "               a",
        "               a",
        "               a",
        "               a",
        "              ##",
        "              a ",
        "              a ",
        "              a ",
        "              ##",
        "              ##"
      ],
      [
        "##   #aaaa#   ##",
        "################",
        "############### ",
        "############### ",
        "############### ",
        "################",
        "###############a",
        "###############a",
        "###############a",
        "###############a",
        "################",
        "############### ",
        "############### ",
        "############### ",
        "################",
        "################"
      ]
    ]
  },
  {
    "type": "part",
    "name": "center10_4",
    "xsize": 16,
    "zsize": 16,
    "slices": [
      [
        "##   #aaaa#   ##",
        "######QSQS######",
        "SQSQSQSQSQSQSQ# ",
        "QSQSQSQSQSQSQS# ",
        "SQSQSQSQSQSQSQ# ",
        "QSQSQSQSQSQSQS##",
        "SQSQSQSQSQSQSQSa",
        "QSQSQSQSQSQSQSQa",
        "SQSQSQSQSQSQSQSa",
        "QSQSQSQSQSQSQSQa",
        "SQSQSQSQSQSQSQ##",
        "QSQSQSQSQSQSQS# ",
        "SQSQSQSQSQSQSQ# ",
        "QSQSQSQSQSQSQS# ",
        "SQSQSQSQSQSQSQ##",
        "QSQSQSQSQSQSQS##"
      ],
      [
        "##   #aaaa#   ##",
        "##aaa#  33#aaa##",
        "    3        3a ",
        " 3            a ",
        "      3  3    a ",
        "   ########   ##",
        "   ++++4CC#N   a",
        "       722#N   a",
        "     7 J22#N   a",
        "   ++++4CC#N   a",
        "   ########   ##",
        "              a ",
        "       7 U 3  a ",
        "   3  3       a ",
        "     3       3##",
        "        3   33##"
      ],
      [
        "##   #aaaa#   ##",
        "##aaa#    #aaa##",
        "              a ",
        "              a ",
        "       T      a ",
        "   ########   ##",
        "   +++++++#*   a",
        "          #*   a",
        "          #*   a",
        "   +++++++#*   a",
        "   ########   ##",
        "       T      a ",
        "              a ",
        "              a ",
        "              ##",
        "              ##"
      ],
      [
        "##   #aaaa#   ##",
        "##aaa#    #aaa##",
        "              a ",
        "              a ",
        "              a ",
        "   ########   ##",
        "   +++++++#    a",
        "          #    a",
        "          #    a",
        "   +++++++#    a",
        "   ########   ##",
        "              a ",
        "              a ",
        "              a ",
        "              ##",
        "              ##"
      ],
      [
        "##   #aaaa#   ##",
        "##aaa#    #aaa##",
        "              a ",
        "              a ",
        "              a ",
        "   ########   ##",
        "   +++++++#    a",
        "          #    a",
        "          #    a",
        "   +++++++#    a",
        "   ########   ##",
        "              a ",
        "              a ",
        "              a ",
        "              ##",
        "              ##"
      ],
      [
